Workbook
Name actualex: 'Pivot Tables'!$C$7
Name actualin: 'Pivot Tables'!$C$5
Name budgetex: 'Pivot Tables'!$B$7
Name budgetin: 'Pivot Tables'!$B$5
Name month: Dashboard!$C$5
Name Slicer_Month: #N/A
Name Slicer_Region: #N/A
Name Slicer_Type: #N/A

Sheet Dashboard with slicers
AS4: =budgetin-budgetex -> 13352367
AS5: =actualin-actualex -> 14548553

Sheet Dashboard
B2: Budget vs. Actual Dashboard
B3: Fiscal Year -> | C3: 2023
B5: Current Month -> | C5: June
B7: Figures in USD | C7: Budget | D7: Actual | F7: Var. Abs. | G7: Var. % | I7: Income: Budget vs Actuals Income | P7: Expenses: Actuals Income
B8: Income:
B9: Product Revenue | C9: =SUMIFS('Clean Ledger Data'!E:E,'Clean Ledger Data'!C:C,Dashboard!B9,'Clean Ledger Data'!B:B,month) -> 19788600 | D9: =SUMIFS('Clean Ledger Data'!F:F,'Clean Ledger Data'!C:C,Dashboard!B9,'Clean Ledger Data'!B:B,Dashboard!$C$5) -> 20308900 | F9: =D9-C9 -> 520300 | G9: =D9/C9-1 -> 0.026292916
B10: Service Revenue | C10: =SUMIFS('Clean Ledger Data'!E:E,'Clean Ledger Data'!C:C,Dashboard!B10,'Clean Ledger Data'!B:B,month) -> 15234500 | D10: =SUMIFS('Clean Ledger Data'!F:F,'Clean Ledger Data'!C:C,Dashboard!B10,'Clean Ledger Data'!B:B,Dashboard!$C$5) -> 15821100 | F10: =D10-C10 -> 586600 | G10: =D10/C10-1 -> 0.03850471
B11: Total Revenue | C11: =SUM(C9:C10) -> 35023100 | D11: =SUM(D9:D10) -> 36130000 | F11: =D11-C11 -> 1106900 | G11: =D11/C11-1 -> 0.031604855
B13: Expenses:
B14: Travel | C14: =SUMIFS('Clean Ledger Data'!E:E,'Clean Ledger Data'!C:C,Dashboard!B14,'Clean Ledger Data'!B:B,month) -> 3116296 | D14: =SUMIFS('Clean Ledger Data'!F:F,'Clean Ledger Data'!C:C,Dashboard!B14,'Clean Ledger Data'!B:B,Dashboard!$C$5) -> 3875731 | F14: =C14-D14 -> -759435 | G14: =C14/D14-1 -> -0.19594626
B15: Infrastructure | C15: =SUMIFS('Clean Ledger Data'!E:E,'Clean Ledger Data'!C:C,Dashboard!B15,'Clean Ledger Data'!B:B,month) -> 3434721 | D15: =SUMIFS('Clean Ledger Data'!F:F,'Clean Ledger Data'!C:C,Dashboard!B15,'Clean Ledger Data'!B:B,Dashboard!$C$5) -> 3855222 | F15: =C15-D15 -> -420501 | G15: =C15/D15-1 -> -0.1090731
B16: Salaries | C16: =SUMIFS('Clean Ledger Data'!E:E,'Clean Ledger Data'!C:C,Dashboard!B16,'Clean Ledger Data'!B:B,month) -> 3308301 | D16: =SUMIFS('Clean Ledger Data'!F:F,'Clean Ledger Data'!C:C,Dashboard!B16,'Clean Ledger Data'!B:B,Dashboard!$C$5) -> 2990415 | F16: =C16-D16 -> 317886 | G16: =C16/D16-1 -> 0.10630163
B17: Utilities | C17: =SUMIFS('Clean Ledger Data'!E:E,'Clean Ledger Data'!C:C,Dashboard!B17,'Clean Ledger Data'!B:B,month) -> 3449591 | D17: =SUMIFS('Clean Ledger Data'!F:F,'Clean Ledger Data'!C:C,Dashboard!B17,'Clean Ledger Data'!B:B,Dashboard!$C$5) -> 3999882 | F17: =C17-D17 -> -550291 | G17: =C17/D17-1 -> -0.13757681
B18: Marketing | C18: =SUMIFS('Clean Ledger Data'!E:E,'Clean Ledger Data'!C:C,Dashboard!B18,'Clean Ledger Data'!B:B,month) -> 4538128 | D18: =SUMIFS('Clean Ledger Data'!F:F,'Clean Ledger Data'!C:C,Dashboard!B18,'Clean Ledger Data'!B:B,Dashboard!$C$5) -> 4334141 | F18: =C18-D18 -> 203987 | G18: =C18/D18-1 -> 0.047065151
B19: Training | C19: =SUMIFS('Clean Ledger Data'!E:E,'Clean Ledger Data'!C:C,Dashboard!B19,'Clean Ledger Data'!B:B,month) -> 4434951 | D19: =SUMIFS('Clean Ledger Data'!F:F,'Clean Ledger Data'!C:C,Dashboard!B19,'Clean Ledger Data'!B:B,Dashboard!$C$5) -> 4938899 | F19: =C19-D19 -> -503948 | G19: =C19/D19-1 -> -0.10203651
B20: Total Expenses | C20: =SUM(C14:C19) -> 22281988 | D20: =SUM(D14:D19) -> 23994290 | F20: =C20-D20 -> -1712302 | G20: =C20/D20-1 -> -0.071362895
B22: Savings | C22: =C11-C20 -> 12741112 | D22: =D11-D20 -> 12135710 | F22: =C22-D22 -> 605402 | G22: =C22/D22-1 -> 0.049885998

Sheet Pivot Tables
A3: Row Labels | B3: Actual | C3: Budget | E3: Sum of Budget | F3: Column Labels
A4: Income | B4: 42582800 | C4: 40626800 | E4: Row Labels | F4: April | G4: Grand Total
A5: April | B5: 42582800 | C5: 40626800 | E5: Infrastructure | F5: 0.049519027 | G5: 0.049519027
A6: Expense | B6: 29230433 | C6: 26078247 | E6: Marketing | F6: 0.052480782 | G6: 0.052480782
A7: April | B7: 29230433 | C7: 26078247 | E7: Product Revenue | F7: 0.35692652 | G7: 0.35692652
A8: Grand Total | B8: 71813233 | C8: 66705047 | E8: Salaries | F8: 0.0519106 | G8: 0.0519106
E9: Service Revenue | F9: 0.25212485 | G9: 0.25212485
E10: Training | F10: 0.057738315 | G10: 0.057738315
E11: Travel | F11: 0.076775795 | G11: 0.076775795
E12: Utilities | F12: 0.10252412 | G12: 0.10252412
E13: Grand Total | F13: 1 | G13: 1
E18: Sum of Actual | F18: Column Labels
E19: Row Labels | F19: April | G19: Grand Total
E20: Infrastructure | F20: 0.058140246 | G20: 0.058140246
E21: Marketing | F21: 0.049030922 | G21: 0.049030922
E22: Product Revenue | F22: 0.34925457 | G22: 0.34925457
E23: Salaries | F23: 0.052450751 | G23: 0.052450751
E24: Service Revenue | F24: 0.24371135 | G24: 0.24371135
E25: Training | F25: 0.054679073 | G25: 0.054679073
E26: Travel | F26: 0.090385584 | G26: 0.090385584
E27: Utilities | F27: 0.1023475 | G27: 0.1023475
E28: Grand Total | F28: 1 | G28: 1
A32: Row Labels | B32: Actual | C32: Budget
A33: South | B33: 12616153 | C33: 11613235
A34: Expense | B34: 5459353 | C34: 4687835
A35: Income | B35: 7156800 | C35: 6925400
A36: North | B36: 13358041 | C36: 12731816
A37: Expense | B37: 5540941 | C37: 5065016
A38: Income | B38: 7817100 | C38: 7666800
A39: West | B39: 14114855 | C39: 12710137
A40: Expense | B40: 6032855 | C40: 4957237
A41: Income | B41: 8082000 | C41: 7752900
A42: Central | B42: 14116846 | C42: 12585031
A43: Expense | B43: 5629546 | C43: 4714931
A44: Income | B44: 8487300 | C44: 7870100
... A48: Grand Total | B48: 71813233 | C48: 66705047

Sheet Clean Ledger Data
A1: Date | B1: Month | C1: Category | D1: Region | E1: Budget | F1: Actual | G1: Payment Method | H1: Transaction ID | I1: Type | K1: category | L1: financial type
A2: 44927 | B2: January | C2: Travel | D2: East | E2: 86427 | F2: 131692 | G2: Bank Transfer | H2: TXN101006 | I2: Expense | K2: {=_xlfn.UNIQUE(C2:C6776)} -> Travel | L2: Expense
A3: 44927 | B3: January | C3: Training | D3: Central | E3: 124753 | F3: 108541 | G3: Cash | H3: TXN101257 | I3: Expense | K3: Training | L3: Expense
A4: 44927 | B4: January | C4: Utilities | D4: South | E4: 51001 | F4: 61785 | G4: UPI | H4: TXN104416 | I4: Expense | K4: Utilities | L4: Expense
A5: 44927 | B5: January | C5: Salaries | D5: South | E5: 122187 | F5: 91982 | G5: Bank Transfer | H5: TXN106436 | I5: Expense | K5: Salaries | L5: Expense
A6: 44927 | B6: January | C6: Utilities | D6: North | E6: 43076 | F6: 112722 | G6: UPI | H6: TXN107415 | I6: Expense | K6: Marketing | L6: Expense
A7: 44927 | B7: January | C7: Training | D7: North | E7: 126539 | F7: 59633 | G7: Cash | H7: TXN108836 | I7: Expense | K7: Product Revenue | L7: Revenue
A8: 44927 | B8: January | C8: Training | D8: West | E8: 31595 | F8: 95129 | G8: Card | H8: TXN108929 | I8: Expense | K8: Service Revenue | L8: Revenue
A9: 44927 | B9: January | C9: Marketing | D9: Central | E9: 69325 | F9: 139614 | G9: Card | H9: TXN109589 | I9: Expense | K9: Infrastructure | L9: Expense
A10: 44927 | B10: January | C10: Salaries | D10: Central | E10: 86411 | F10: 147199 | G10: Bank Transfer | H10: TXN109819 | I10: Expense
A11: 44927 | B11: January | C11: Product Revenue | D11: East | E11: 226100 | F11: 291600 | G11: Card | H11: REV100372 | I11: Income
A12: 44927 | B12: January | C12: Service Revenue | D12: Central | E12: 46300 | F12: 44100 | G12: Card | H12: REV100459 | I12: Income
A13: 44927 | B13: January | C13: Service Revenue | D13: South | E13: 66800 | F13: 69000 | G13: UPI | H13: REV101524 | I13: Income
A14: 44927 | B14: January | C14: Service Revenue | D14: South | E14: 137500 | F14: 121400 | G14: Card | H14: REV102177 | I14: Income
A15: 44927 | B15: January | C15: Product Revenue | D15: North | E15: 136600 | F15: 109900 | G15: Bank Transfer | H15: REV102517 | I15: Income
A16: 44927 | B16: January | C16: Product Revenue | D16: North | E16: 151500 | F16: 145000 | G16: Bank Transfer | H16: REV102993 | I16: Income
A17: 44927 | B17: January | C17: Product Revenue | D17: West | E17: 233400 | F17: 244100 | G17: Bank Transfer | H17: REV103023 | I17: Income
A18: 44927 | B18: January | C18: Service Revenue | D18: Central | E18: 74800 | F18: 80900 | G18: Bank Transfer | H18: REV103240 | I18: Income
A19: 44927 | B19: January | C19: Service Revenue | D19: Central | E19: 139800 | F19: 187900 | G19: Card | H19: REV103325 | I19: Income
A20: 44928 | B20: January | C20: Salaries | D20: North | E20: 23118 | F20: 119354 | G20: Bank Transfer | H20: TXN100509 | I20: Expense
A21: 44928 | B21: January | C21: Travel | D21: East | E21: 105614 | F21: 55318 | G21: Card | H21: TXN100517 | I21: Expense
... A868: 44976 | B868: February | C868: Infrastructure | D868: Central | E868: 95638 | F868: 111028 | G868: Card | H868: TXN109816 | I868: Expense
A869: 44976 | B869: February | C869: Salaries | D869: East | E869: 17385 | F869: 79153 | G869: UPI | I869: Expense
A870: 44976 | B870: February | C870: Service Revenue | D870: South | E870: 154400 | F870: 120500 | G870: UPI | H870: REV100031 | I870: Income
A871: 44976 | B871: February | C871: Service Revenue | D871: Central | E871: 114200 | F871: 136400 | G871: Bank Transfer | H871: REV100707 | I871: Income
A872: 44976 | B872: February | C872: Product Revenue | D872: South | E872: 97200 | F872: 80400 | G872: Bank Transfer | H872: REV100858 | I872: Income
A873: 44976 | B873: February | C873: Product Revenue | D873: East | E873: 56500 | F873: 46000 | G873: Bank Transfer | H873: REV101245 | I873: Income
A874: 44976 | B874: February | C874: Service Revenue | D874: Central | E874: 82600 | F874: 90700 | G874: Card | H874: REV101259 | I874: Income
A875: 44976 | B875: February | C875: Service Revenue | D875: North | E875: 67000 | F875: 83600 | G875: UPI | H875: REV101536 | I875: Income
A876: 44976 | B876: February | C876: Service Revenue | D876: East | E876: 57200 | F876: 66300 | G876: UPI | H876: REV101799 | I876: Income
A877: 44976 | B877: February | C877: Service Revenue | D877: North | E877: 79800 | F877: 70200 | G877: Bank Transfer | H877: REV101933 | I877: Income
A878: 44976 | B878: February | C878: Service Revenue | D878: South | E878: 109800 | F878: 100900 | G878: Bank Transfer | H878: REV102290 | I878: Income
A879: 44976 | B879: February | C879: Product Revenue | D879: North | E879: 156300 | F879: 190400 | G879: Bank Transfer | H879: REV102997 | I879: Income
A880: 44976 | B880: February | C880: Service Revenue | D880: North | E880: 86700 | F880: 97900 | G880: Card | H880: REV103202 | I880: Income
A881: 44976 | B881: February | C881: Service Revenue | D881: Central | E881: 103100 | F881: 101600 | G881: Bank Transfer | H881: REV103324 | I881: Income
... A1674: 45020 | B1674: April | C1674: Marketing | D1674: North | E1674: 41572 | F1674: 77100 | G1674: UPI | H1674: TXN109811 | I1674: Expense
A1675: 45020 | B1675: April | C1675: Marketing | D1675: South | E1675: 27025 | F1675: 48529 | G1675: Card | I1675: Expense
A1676: 45020 | B1676: April | C1676: Product Revenue | D1676: South | E1676: 157200 | F1676: 173200 | G1676: Bank Transfer | H1676: REV100182 | I1676: Income
A1677: 45020 | B1677: April | C1677: Product Revenue | D1677: South | E1677: 73200 | F1677: 87900 | G1677: UPI | H1677: REV100205 | I1677: Income
A1678: 45020 | B1678: April | C1678: Product Revenue | D1678: South | E1678: 111900 | F1678: 121400 | G1678: Bank Transfer | H1678: REV101045 | I1678: Income
...
